{"uuid": "b5eb257d-ff81-43ae-bb80-e6ab1641939a", "children": ["c68ce0aa-c46a-496c-9f0e-ea0359261299"], "befores": [{"name": "create_driver", "status": "broken", "statusDetails": {"message": "selenium.common.exceptions.WebDriverException: Message: Could not start Mobile Browser.\n Reason: \nAn unknown server-side error occurred while processing the command. Original error: Cannot start the 'org.wikipedia.alpha' application. Visit https://github.com/appium/appium/blob/master/docs/en/writing-running-appium/android/activity-startup.md for troubleshooting. Original error: 'ru.vkusvill.*' or 'org.wikipedia.alpha.ru.vkusvill.*' never started. Visit https://github.com/appium/appium/blob/master/docs/en/writing-running-appium/android/activity-startup.md for troubleshooting\n\n", "trace": "  File \"/Library/Frameworks/Python.framework/Versions/3.10/lib/python3.10/site-packages/pluggy/callers.py\", line 187, in _multicall\n    res = hook_impl.function(*args)\n  File \"/Library/Frameworks/Python.framework/Versions/3.10/lib/python3.10/site-packages/_pytest/fixtures.py\", line 1121, in pytest_fixture_setup\n    result = call_fixture_func(fixturefunc, request, kwargs)\n  File \"/Library/Frameworks/Python.framework/Versions/3.10/lib/python3.10/site-packages/_pytest/fixtures.py\", line 900, in call_fixture_func\n    fixture_result = fixturefunc(**kwargs)\n  File \"/Users/a11/Documents/qa.guru/qa_guru_python_lesson_final/test/conftest.py\", line 86, in create_driver\n    browser.config.driver = webdriver.Remote(\n  File \"/Library/Frameworks/Python.framework/Versions/3.10/lib/python3.10/site-packages/selenium/webdriver/remote/webdriver.py\", line 270, in __init__\n    self.start_session(capabilities, browser_profile)\n  File \"/Library/Frameworks/Python.framework/Versions/3.10/lib/python3.10/site-packages/selenium/webdriver/remote/webdriver.py\", line 363, in start_session\n    response = self.execute(Command.NEW_SESSION, parameters)\n  File \"/Library/Frameworks/Python.framework/Versions/3.10/lib/python3.10/site-packages/selenium/webdriver/remote/webdriver.py\", line 428, in execute\n    self.error_handler.check_response(response)\n  File \"/Library/Frameworks/Python.framework/Versions/3.10/lib/python3.10/site-packages/selenium/webdriver/remote/errorhandler.py\", line 243, in check_response\n    raise exception_class(message, screen, stacktrace)\n"}, "start": 1667661645210, "stop": 1667661692785}], "start": 1667661645210, "stop": 1667661692897}